<mujoco model="panda">
  <default>
    <default class="robot">
      <joint limited="true" damping="0.01" armature="0.01" frictionloss="0.01" actuatorfrcrange="-1000 1000" />
      <default class="visual">
        <geom material="visualgeom" contype="0" conaffinity="0" group="2" />
      </default>
      <default class="collision">
        <geom condim="6" conaffinity="15" friction="0.8 0.02 0.01" solimp="0.015 1 0.036" group="3" />
      </default>
    </default>
  </default>

  <compiler angle="radian" meshdir="meshes" />

  <option integrator="implicitfast" cone="elliptic" impratio="100" />

  <visual>
    <global ellipsoidinertia="true" />
  </visual>

  <asset>
    <material name="panda_white" rgba="1. 1. 1. 1." />
    <material name="default_material" rgba="0.7 0.7 0.7 1" />
    <mesh name="link0.obj" file="link0.obj" />
    <mesh name="link1.obj" file="link1.obj" />
    <mesh name="link2.obj" file="link2.obj" />
    <mesh name="link3.obj" file="link3.obj" />
    <mesh name="link4.obj" file="link4.obj" />
    <mesh name="link5.obj" file="link5.obj" />
    <mesh name="link6.obj" file="link6.obj" />
    <mesh name="link7.obj" file="link7.obj" />
    <mesh name="hand.obj" file="hand.obj" />
    <mesh name="finger.obj" file="finger.obj" />
  </asset>

  <worldbody>
    <light name="top" pos="0 0 30"/>
    <camera name="front_view" pos="0.0 -2.5 1.7" quat="0.8660254037844386 0.5 0.0 0.0" mode="fixed"/>
    <body name="table" pos="0.4 0 -0.5">
      <geom name="table_collision" type="box" size="0.5 0.5 0.5" class="collision" />
      <geom name="table_visual" material="default_material" type="box" size="0.5 0.5 0.5" class="visual" />
    </body>
    <body name="obstacle1" pos="0.4 0.3 0.3">
      <geom name="obstacle1_collision" type="box" size="0.2 0.1 0.3" class="collision" />
      <geom name="obstacle1_visual" rgba="0 0 1 1" material="default_material" type="box" size="0.2 0.1 0.3" class="visual" />
    </body>
    <body name="obstacle2" pos="0.4 -0.3 0.3">
      <geom name="obstacle2_collision" type="box" size="0.2 0.1 0.3" class="collision" />
      <geom name="obstacle2_visual" rgba="0 0 1 1" material="default_material" type="box" size="0.2 0.1 0.3" class="visual" />
    </body>
    <body name="panda_link0" childclass="robot" pos="0.0 0.0 0.0">
      <freejoint name="floating_base" />
      <geom name="panda_link0_collision" type="mesh" mesh="link0.obj" class="collision" />
      <geom name="panda_link0_visual" material="panda_white" type="mesh" mesh="link0.obj" class="visual" />
      <body name="panda_link1" pos="0 0 0.333">
        <joint name="panda_joint1" type="hinge" range="-2.9671 2.9671" axis="0 0 1" />
        <geom name="panda_link1_collision" type="mesh" mesh="link1.obj" class="collision" />
        <geom name="panda_link1_visual" material="panda_white" type="mesh" mesh="link1.obj" class="visual" />
        <body name="panda_link2" quat="0.7071067811882787 -0.7071067811848163 0.0 0.0">
          <joint name="panda_joint2" type="hinge" range="-1.8326 1.8326" axis="0 0 1" />
          <geom name="panda_link2_collision" type="mesh" mesh="link2.obj" class="collision" />
          <geom name="panda_link2_visual" material="panda_white" type="mesh" mesh="link2.obj" class="visual" />
          <body name="panda_link3" pos="0 -0.316 0" quat="0.7071067811882787 0.7071067811848163 0.0 0.0">
            <joint name="panda_joint3" type="hinge" range="-2.9671 2.9671" axis="0 0 1" />
            <geom name="panda_link3_collision" type="mesh" mesh="link3.obj" class="collision" />
            <geom name="panda_link3_visual" material="panda_white" type="mesh" mesh="link3.obj" class="visual" />
            <body name="panda_link4" pos="0.0825 0 0" quat="0.7071067811882787 0.7071067811848163 0.0 0.0">
              <joint name="panda_joint4" type="hinge" range="-3.1416 0.0" axis="0 0 1" />
              <geom name="panda_link4_collision" type="mesh" mesh="link4.obj" class="collision" />
              <geom name="panda_link4_visual" material="panda_white" type="mesh" mesh="link4.obj" class="visual" />
              <body name="panda_link5" pos="-0.0825 0.384 0" quat="0.7071067811882787 -0.7071067811848163 0.0 0.0">
                <joint name="panda_joint5" type="hinge" range="-2.9671 2.9671" axis="0 0 1" />
                <geom name="panda_link5_collision" type="mesh" mesh="link5.obj" class="collision" />
                <geom name="panda_link5_visual" material="panda_white" type="mesh" mesh="link5.obj" class="visual" />
                <body name="panda_link6" quat="0.7071067811882787 0.7071067811848163 0.0 0.0">
                  <joint name="panda_joint6" type="hinge" range="-0.0873 3.8223" axis="0 0 1" />
                  <geom name="panda_link6_collision" type="mesh" mesh="link6.obj" class="collision" />
                  <geom name="panda_link6_visual" material="panda_white" type="mesh" mesh="link6.obj" class="visual" />
                  <body name="panda_link7" pos="0.088 0 0" quat="0.7071067811882787 0.7071067811848163 0.0 0.0">
                    <joint name="panda_joint7" type="hinge" range="-2.9671 2.9671" axis="0 0 1" />
                    <geom name="panda_link7_collision" type="mesh" mesh="link7.obj" class="collision" />
                    <geom name="panda_link7_visual" material="panda_white" type="mesh" mesh="link7.obj" class="visual" />
                    <body name="panda_link8" pos="0 0 0.107">
                      <body name="panda_hand" quat="0.9238795325113726 0.0 0.0 -0.38268343236488267">
                        <geom name="panda_hand_collision" type="mesh" mesh="hand.obj" class="collision" />
                        <geom name="panda_hand_visual" material="panda_white" type="mesh" mesh="hand.obj" class="visual" />
                        <body name="panda_leftfinger" pos="0 0 0.0584">
                          <joint name="panda_finger_joint1" type="slide" range="0.0 0.04" axis="0 1 0" />
                          <geom name="panda_leftfinger_collision" type="mesh" mesh="finger.obj" class="collision" />
                          <geom name="panda_leftfinger_visual" material="panda_white" type="mesh" mesh="finger.obj" class="visual" />
                        </body>
                        <body name="panda_rightfinger" pos="0 0 0.0584">
                          <joint name="panda_finger_joint2" type="slide" range="0.0 0.04" axis="0 -1 0" />
                          <geom name="panda_rightfinger_collision" quat="-1.0341155355510722e-13 -0.0 0.0 1.0" type="mesh" mesh="finger.obj" class="collision" />
                          <geom name="panda_rightfinger_visual" quat="-1.0341155355510722e-13 -0.0 0.0 1.0" material="panda_white" type="mesh" mesh="finger.obj" class="visual" />
                        </body>
                      </body>
                    </body>
                  </body>
                </body>
              </body>
            </body>
          </body>
        </body>
      </body>
      <site name="panda_link0_site" />
    </body>
    <body name="block" pos="0.6 0.0 .03" quat="0.96592583 0.0 0.0 0.25881905">
      <geom name="block_collision" type="box" size="0.03 0.03 0.03" class="collision" />
      <geom name="block_visual" material="default_material" rgba="1.0 0.0 0.0 1.0" type="box" size="0.03 0.03 0.03" class="visual" />  
    </body>
  </worldbody>

  <actuator>
    <position name="panda_joint1_ctrl" joint="panda_joint1" kp="1000" forcerange="-87.00000000 87.00000000" forcelimited="true" ctrlrange="-2.9671 2.9671" ctrllimited="true" class="robot" />
    <position name="panda_joint2_ctrl" joint="panda_joint2" kp="1000" forcerange="-87.00000000 87.00000000" forcelimited="true" ctrlrange="-1.8326 1.8326" ctrllimited="true" class="robot" />
    <position name="panda_joint3_ctrl" joint="panda_joint3" kp="1000"  forcerange="-87.00000000 87.00000000"forcelimited="true" ctrlrange="-2.9671 2.9671" ctrllimited="true" class="robot" />
    <position name="panda_joint4_ctrl" joint="panda_joint4" kp="1000"  forcerange="-87.00000000 87.00000000"forcelimited="true" ctrlrange="-3.1416 0.0" ctrllimited="true" class="robot" />
    <position name="panda_joint5_ctrl" joint="panda_joint5" kp="1000"  forcerange="-12.00000000 12.00000000"forcelimited="true" ctrlrange="-2.9671 2.9671" ctrllimited="true" class="robot" />
    <position name="panda_joint6_ctrl" joint="panda_joint6" kp="1000"  forcerange="-12.00000000 12.00000000"forcelimited="true" ctrlrange="-0.0873 3.8223" ctrllimited="true" class="robot" />
    <position name="panda_joint7_ctrl" joint="panda_joint7" kp="1000"  forcerange="-12.00000000 12.00000000"forcelimited="true" ctrlrange="-2.9671 2.9671" ctrllimited="true" class="robot" />
    <position name="panda_finger_joint1_ctrl" joint="panda_finger_joint1" kp="1000" forcerange="-20.00000000 20.00000000" forcelimited="true" ctrlrange="0.0 0.04" ctrllimited="true" class="robot" />
    <position name="panda_finger_joint2_ctrl" joint="panda_finger_joint2" kp="1000" forcerange="-20.00000000 20.00000000" forcelimited="true" ctrlrange="0.0 0.04" ctrllimited="true" class="robot" />
  </actuator>

  <contact>
    <exclude body1="table" body2="obstacle1" />
    <exclude body1="table" body2="obstacle2" />
    <exclude body1="table" body2="panda_link0" />
    <exclude body1="panda_link0" body2="panda_link1" />
    <exclude body1="panda_link1" body2="panda_link2" />
    <exclude body1="panda_link2" body2="panda_link3" />
    <exclude body1="panda_link3" body2="panda_link4" />
    <exclude body1="panda_link4" body2="panda_link5" />
    <exclude body1="panda_link5" body2="panda_link6" />
    <exclude body1="panda_link6" body2="panda_link7" />
    <exclude body1="panda_hand" body2="panda_leftfinger" />
    <exclude body1="panda_hand" body2="panda_rightfinger" />
  </contact>

  <sensor>
    <framepos name="base_link_pos" objtype="site" objname="panda_link0_site" />
    <framequat name="base_link_quat" objtype="site" objname="panda_link0_site" />
    <framelinvel name="base_link_vel" objtype="site" objname="panda_link0_site" />
    <frameangvel name="base_link_ang_vel" objtype="site" objname="panda_link0_site" />
  </sensor>

  <equality>
    <weld body1="panda_link0" body2="table"/>
  </equality>
</mujoco>